Workbook
Name alcoben: #REF!

Sheet hechos
A1: provincia | B1: localidad | C1: Nombre | D1: Direccion | E1: Telefono | F1: Mail | G1: Category | H1: Website | J1: precio | K1: cpm | L1: miles | M1: registros | N1: url
A2: A Coruña | B2: A Aldea De Arriba (Santa Marta De Babio - Bergondo) | C2: 497 | D2: 488 | E2: 425 | F2: 185 | G2: 468 | H2: 335 | J2: =+K2*L2 -> 2.982 | K2: 6 | L2: =+M2/1000 -> 0.497 | M2: =+C2 -> 497 | N2: https://gsas.es/producto/base-de-datos-de-empresas-de-la-localidad-de-a-aldea-de-arriba-en-la-provincia-de-a-coruna/
A3: A Coruña | B3: A Barcala Cambre) | C3: 315 | D3: 313 | E3: 264 | F3: 78 | G3: 293 | H3: 157 | J3: =+K3*L3 -> 1.89 | K3: 6 | L3: =+M3/1000 -> 0.315 | M3: =+C3 -> 315 | N3: https://gsas.es/producto/base-de-datos-de-empresas-de-la-localidad-de-a-barcala-en-la-provincia-de-a-coruna/
A4: A Coruña | B4: A Brea, (Carballo) | C4: 746 | D4: 739 | E4: 595 | F4: 116 | G4: 732 | H4: 309 | J4: =+K4*L4 -> 4.476 | K4: 6 | L4: =+M4/1000 -> 0.746 | M4: =+C4 -> 746 | N4: https://gsas.es/producto/base-de-datos-de-empresas-de-la-localidad-de-a-brea-en-la-provincia-de-a-coruna/
A5: A Coruña | B5: A Coruña - La Coruña | C5: 12763 | D5: 12639 | E5: 10696 | F5: 3709 | G5: 12401 | H5: 8066 | J5: =+K5*L5 -> 63.815 | K5: 5 | L5: =+M5/1000 -> 12.763 | M5: =+C5 -> 12763 | N5: https://gsas.es/producto/base-de-datos-de-empresas-de-la-localidad-de-la-coruna-en-la-provincia-de-a-coruna/
A6: A Coruña | B6: Abegondo | C6: 360 | D6: 329 | E6: 209 | F6: 60 | G6: 331 | H6: 139 | J6: =+K6*L6 -> 2.16 | K6: 6 | L6: =+M6/1000 -> 0.36 | M6: =+C6 -> 360 | N6: https://gsas.es/producto/base-de-datos-de-empresas-de-la-localidad-de-abegondo-en-la-provincia-de-a-coruna/
A7: A Coruña | B7: Acea Da Ma (Fonteculler) | C7: 638 | D7: 625 | E7: 526 | F7: 145 | G7: 620 | H7: 366 | J7: =+K7*L7 -> 3.828 | K7: 6 | L7: =+M7/1000 -> 0.638 | M7: =+C7 -> 638 | N7: https://gsas.es/producto/base-de-datos-de-empresas-de-la-localidad-de-acea-da-ma-en-la-provincia-de-a-coruna/
A8: A Coruña | B8: Acea De Ama (O Burgo) | C8: 608 | D8: 603 | E8: 503 | F8: 158 | G8: 588 | H8: 335 | J8: =+K8*L8 -> 3.648 | K8: 6 | L8: =+M8/1000 -> 0.608 | M8: =+C8 -> 608 | N8: https://gsas.es/producto/base-de-datos-de-empresas-de-la-localidad-de-acea-de-ama-en-la-provincia-de-a-coruna/
A9: A Coruña | B9: Aeropuerto De Alvedro | C9: 373 | D9: 368 | E9: 325 | F9: 129 | G9: 361 | H9: 276 | J9: =+K9*L9 -> 2.238 | K9: 6 | L9: =+M9/1000 -> 0.373 | M9: =+C9 -> 373 | N9: https://gsas.es/producto/base-de-datos-de-empresas-de-la-localidad-de-aeropuerto-de-alvedro-en-la-provincia-de-a-coruna/
A10: A Coruña | B10: Agoso (Santa Baia De Oza - Teo) | C10: 461 | D10: 432 | E10: 345 | F10: 134 | G10: 430 | H10: 270 | J10: =+K10*L10 -> 2.766 | K10: 6 | L10: =+M10/1000 -> 0.461 | M10: =+C10 -> 461 | N10: https://gsas.es/producto/base-de-datos-de-empresas-de-la-localidad-de-agoso-en-la-provincia-de-a-coruna/
A11: A Coruña | B11: Agras (Nosa Señora Dos Desamparados De Xubia - Naron) | C11: 368 | D11: 363 | E11: 290 | F11: 66 | G11: 353 | H11: 163 | J11: =+K11*L11 -> 2.208 | K11: 6 | L11: =+M11/1000 -> 0.368 | M11: =+C11 -> 368 | N11: https://gsas.es/producto/base-de-datos-de-empresas-de-la-localidad-de-agras-en-la-provincia-de-a-coruna/
A12: A Coruña | B12: Aldea Nova | C12: 757 | D12: 744 | E12: 649 | F12: 235 | G12: 741 | H12: 470 | J12: =+K12*L12 -> 4.542 | K12: 6 | L12: =+M12/1000 -> 0.757 | M12: =+C12 -> 757 | N12: https://gsas.es/producto/base-de-datos-de-empresas-de-la-localidad-de-aldea-nova-en-la-provincia-de-a-coruna/
A13: A Coruña | B13: Alto Del Castaño (San Xose Obreiro De Xubia - Naron) | C13: 1583 | D13: 1567 | E13: 1315 | F13: 455 | G13: 1539 | H13: 944 | J13: =+K13*L13 -> 9.498 | K13: 6 | L13: =+M13/1000 -> 1.583 | M13: =+C13 -> 1583 | N13: https://gsas.es/producto/base-de-datos-de-empresas-de-la-localidad-de-alto-del-castano-en-la-provincia-de-a-coruna/
... A62: Alava | B62: Oion | C62: 329 | D62: 322 | E62: 253 | F62: 100 | G62: 305 | H62: 188 | J62: =+K62*L62 -> 1.974 | K62: 6 | L62: =+M62/1000 -> 0.329 | M62: =+C62 -> 329 | N62: https://gsas.es/producto/base-de-datos-de-empresas-de-la-localidad-de-oion-en-la-provincia-de-alava/
A63: Alava | B63: Vitoria - Gasteiz | C63: 14738 | D63: 14473 | E63: 12528 | F63: 4567 | G63: 14528 | H63: 9391 | J63: =+K63*L63 -> 73.69 | K63: 5 | L63: =+M63/1000 -> 14.738 | M63: =+C63 -> 14738 | N63: https://gsas.es/producto/base-de-datos-de-empresas-de-la-localidad-de-vitoria-gastegiz-en-la-provincia-de-alava-araba/ | O63: wordpress pone que no existe
A64: Albacete | B64: Albacete | C64: 10266 | D64: 9928 | E64: 8660 | F64: 2993 | G64: 9949 | H64: 6282 | J64: =+K64*L64 -> 51.33 | K64: 5 | L64: =+M64/1000 -> 10.266 | M64: =+C64 -> 10266 | N64: https://gsas.es/producto/base-de-datos-de-empresas-de-la-localidad-de-albacete-en-la-provincia-de-albacete/
A65: Albacete | B65: Almansa | C65: 1517 | D65: 1485 | E65: 1254 | F65: 431 | G65: 1443 | H65: 889 | J65: =+K65*L65 -> 9.102 | K65: 6 | L65: =+M65/1000 -> 1.517 | M65: =+C65 -> 1517 | N65: https://gsas.es/producto/base-de-datos-de-empresas-de-la-localidad-de-almansa-en-la-provincia-de-albacete/
A66: Albacete | B66: Casas - Ibañez | C66: 387 | D66: 374 | E66: 321 | F66: 102 | G66: 376 | H66: 211 | J66: =+K66*L66 -> 2.322 | K66: 6 | L66: =+M66/1000 -> 0.387 | M66: =+C66 -> 387 | N66: https://gsas.es/producto/base-de-datos-de-empresas-de-la-localidad-de-casas-ibanez-en-la-provincia-de-albacete/
A67: Albacete | B67: Caudete | C67: 609 | D67: 593 | E67: 457 | F67: 122 | G67: 597 | H67: 290 | J67: =+K67*L67 -> 3.654 | K67: 6 | L67: =+M67/1000 -> 0.609 | M67: =+C67 -> 609 | N67: https://gsas.es/producto/base-de-datos-de-empresas-de-la-localidad-de-caudete-en-la-provincia-de-albacete/
A68: Albacete | B68: Chinchilla De Monte Aragon | C68: 357 | D68: 353 | E68: 237 | F68: 83 | G68: 343 | H68: 190 | J68: =+K68*L68 -> 2.142 | K68: 6 | L68: =+M68/1000 -> 0.357 | M68: =+C68 -> 357 | N68: https://gsas.es/producto/base-de-datos-de-empresas-de-la-localidad-de-chinchilla-de-monte-aragon-en-la-provincia-de-albacete/
A69: Albacete | B69: Hellin | C69: 1460 | D69: 1411 | E69: 1188 | F69: 337 | G69: 1404 | H69: 813 | J69: =+K69*L69 -> 8.76 | K69: 6 | L69: =+M69/1000 -> 1.46 | M69: =+C69 -> 1460 | N69: https://gsas.es/producto/base-de-datos-de-empresas-de-la-localidad-de-hellin-en-la-provincia-de-albacete/
A70: Albacete | B70: La Roda | C70: 1027 | D70: 997 | E70: 759 | F70: 216 | G70: 1007 | H70: 530 | J70: =+K70*L70 -> 6.162 | K70: 6 | L70: =+M70/1000 -> 1.027 | M70: =+C70 -> 1027 | N70: https://gsas.es/producto/base-de-datos-de-empresas-de-la-localidad-de-la-roda-en-la-provincia-de-albacete/
A71: Albacete | B71: Tobarra | C71: 388 | D71: 378 | E71: 290 | F71: 67 | G71: 374 | H71: 151 | J71: =+K71*L71 -> 2.328 | K71: 6 | L71: =+M71/1000 -> 0.388 | M71: =+C71 -> 388 | N71: https://gsas.es/producto/base-de-datos-de-empresas-de-la-localidad-de-tobarra-en-la-provincia-de-albacete/
A72: Albacete | B72: Villarrobledo | C72: 1562 | D72: 1488 | E72: 1264 | F72: 405 | G72: 1511 | H72: 886 | J72: =+K72*L72 -> 9.372 | K72: 6 | L72: =+M72/1000 -> 1.562 | M72: =+C72 -> 1562 | N72: https://gsas.es/producto/base-de-datos-de-empresas-de-la-localidad-de-villarrobledo-en-la-provincia-de-albacete/
A73: Alicante - Alicante | B73: Abio | C73: 524 | D73: 516 | E73: 398 | F73: 116 | G73: 514 | H73: 279 | J73: =+K73*L73 -> 3.144 | K73: 6 | L73: =+M73/1000 -> 0.524 | M73: =+C73 -> 524 | N73: https://gsas.es/producto/base-de-datos-de-empresas-de-la-localidad-de-abio-en-la-provincia-de-alicante/
A74: Alicante - Alicante | B74: Agost | C74: 346 | D74: 337 | E74: 259 | F74: 85 | G74: 337 | H74: 187 | J74: =+K74*L74 -> 2.076 | K74: 6 | L74: =+M74/1000 -> 0.346 | M74: =+C74 -> 346 | N74: https://gsas.es/producto/base-de-datos-de-empresas-de-la-localidad-de-agost-en-la-provincia-de-alicante/
A75: Alicante - Alicante | B75: Aixihuili | C75: 2116 | D75: 2048 | E75: 1659 | F75: 481 | G75: 2088 | H75: 1181 | J75: =+K75*L75 -> 12.696 | K75: 6 | L75: =+M75/1000 -> 2.116 | M75: =+C75 -> 2116 | N75: https://gsas.es/producto/base-de-datos-de-empresas-de-la-localidad-de-partida-aixihuili-en-la-provincia-de-alicante/
... A80: Alicante - Alicante | B80: Alicante - Alacant | C80: 18270 | D80: 18074 | E80: 15651 | F80: 5549 | G80: 17932 | H80: 11713 | J80: =+K80*L80 -> 73.08 | K80: 4 | L80: =+M80/1000 -> 18.27 | M80: =+C80 -> 18270 | N80: https://gsas.es/producto/base-de-datos-de-empresas-de-la-localidad-de-alicante-alacant-en-la-provincia-de-alicante-alacant/
A81: Alicante - Alicante | B81: Almafra | C81: 2037 | D81: 2013 | E81: 1599 | F81: 468 | G81: 1997 | H81: 1142 | J81: 3.888 | K81: 6 | L81: 0.648 | M81: 648 | N81: https://gsas.es/producto/base-de-datos-de-empresas-de-la-localidad-de-almafra-en-la-provincia-de-alicante/
A82: Alicante - Alicante | B82: Almajal | C82: 1065 | D82: 1020 | E82: 840 | F82: 194 | G82: 1037 | H82: 562 | J82: =+K82*L82 -> 6.39 | K82: 6 | L82: =+M82/1000 -> 1.065 | M82: =+C82 -> 1065 | N82: https://gsas.es/producto/base-de-datos-de-empresas-de-la-localidad-de-almajal-en-la-provincia-de-alicante/
A83: Alicante - Alicante | B83: Almedia | C83: 478 | D83: 468 | E83: 381 | F83: 110 | G83: 467 | H83: 249 | J83: =+K83*L83 -> 2.868 | K83: 6 | L83: =+M83/1000 -> 0.478 | M83: =+C83 -> 478 | N83: https://gsas.es/producto/base-de-datos-de-empresas-de-la-localidad-de-almedia-en-la-provincia-de-alicante/
A84: Alicante - Alicante | B84: Almoradi | C84: 1237 | D84: 1232 | E84: 1078 | F84: 328 | G84: 1191 | H84: 735 | J84: =+K84*L84 -> 7.422 | K84: 6 | L84: =+M84/1000 -> 1.237 | M84: =+C84 -> 1237 | N84: https://gsas.es/producto/base-de-datos-de-empresas-de-la-localidad-de-almoradi-en-la-provincia-de-alicante/
A85: Alicante - Alicante | B85: Alquebla | C85: 513 | D85: 508 | E85: 423 | F85: 96 | G85: 493 | H85: 260 | J85: 3.078 | K85: 6 | L85: 0.513 | M85: 513 | N85: https://gsas.es/producto/base-de-datos-de-empresas-de-la-localidad-de-alquebla-en-la-provincia-de-alicante/
A86: Alicante - Alicante | B86: Altea | C86: 2745 | D86: 2621 | E86: 2311 | F86: 742 | G86: 2705 | H86: 1691 | J86: =+K86*L86 -> 16.47 | K86: 6 | L86: =+M86/1000 -> 2.745 | M86: =+C86 -> 2745 | N86: https://gsas.es/producto/base-de-datos-de-empresas-de-la-localidad-de-altea-en-la-provincia-de-alicante-alacant/
A87: Alicante - Alicante | B87: Altomira | C87: 4462 | D87: 4429 | E87: 3865 | F87: 1371 | G87: 4390 | H87: 2959 | J87: =+K87*L87 -> 26.772 | K87: 6 | L87: =+M87/1000 -> 4.462 | M87: =+C87 -> 4462 | N87: https://gsas.es/producto/base-de-datos-de-empresas-de-la-localidad-de-altomira-en-la-provincia-de-alicante-alacant/
A88: Alicante - Alicante | B88: Aspe | C88: 1322 | D88: 1295 | E88: 1079 | F88: 307 | G88: 1282 | H88: 717 | J88: =+K88*L88 -> 7.932 | K88: 6 | L88: =+M88/1000 -> 1.322 | M88: =+C88 -> 1322 | N88: https://gsas.es/producto/base-de-datos-de-empresas-de-la-localidad-de-aspe-en-la-provincia-de-alicante/
A89: Alicante - Alicante | B89: Bacarot | C89: 343 | D89: 338 | E89: 302 | F89: 149 | G89: 335 | H89: 249 | J89: =+K89*L89 -> 2.058 | K89: 6 | L89: =+M89/1000 -> 0.343 | M89: =+C89 -> 343 | N89: https://gsas.es/producto/base-de-datos-de-empresas-de-la-localidad-de-bacarot-en-la-provincia-de-alicante/
A90: Alicante - Alicante | B90: Baladrar | C90: 1340 | D90: 1317 | E90: 1055 | F90: 401 | G90: 1316 | H90: 863 | J90: 3.558 | K90: 6 | L90: 0.593 | M90: 593 | N90: https://gsas.es/producto/base-de-datos-de-empresas-de-la-localidad-de-baladrar-en-la-provincia-de-alicante/
A91: Alicante - Alicante | B91: Banyeres De Mariola | C91: 593 | D91: 582 | E91: 484 | F91: 184 | G91: 583 | H91: 345 | J91: =+K91*L91 -> 3.558 | K91: 6 | L91: =+M91/1000 -> 0.593 | M91: =+C91 -> 593 | N91: https://gsas.es/producto/base-de-datos-de-empresas-de-la-localidad-de-banyeres-de-mariola-en-la-provincia-de-alicante/
A92: Alicante - Alicante | B92: Barranco Parra | C92: 719 | D92: 706 | E92: 585 | F92: 216 | G92: 701 | H92: 431 | J92: 3.306 | K92: 6 | L92: 0.551 | M92: 551 | N92: https://gsas.es/producto/base-de-datos-de-empresas-de-la-localidad-de-barranco-parra-en-la-provincia-de-alicante/
...

Sheet revisado
A1: provincia | B1: localidad | C1: Nombre | D1: Direccion | E1: Telefono | F1: Mail | G1: Category | H1: Website | J1: precio | K1: cpm | L1: miles | M1: registros
A2: Cordoba | B2: Aguilar De La Frontera | C2: 576 | D2: 565 | E2: 460 | F2: 96 | G2: 559 | H2: 264 | J2: =+K2*L2 -> 3.456 | K2: 6 | L2: =+M2/1000 -> 0.576 | M2: =+C2 -> 576
A3: Cordoba | B3: Aladid | C3: 1144 | D3: 1127 | E3: 910 | F3: 216 | G3: 1115 | H3: 555 | J3: =+K3*L3 -> 6.864 | K3: 6 | L3: =+M3/1000 -> 1.144 | M3: =+C3 -> 1144
A4: Cordoba | B4: Algarbes | C4: 801 | D4: 786 | E4: 602 | F4: 171 | G4: 777 | H4: 525 | J4: =+K4*L4 -> 4.806 | K4: 6 | L4: =+M4/1000 -> 0.801 | M4: =+C4 -> 801
A5: Cordoba | B5: Almodovar Del Rio | C5: 365 | D5: 346 | E5: 260 | F5: 59 | G5: 349 | H5: 164 | J5: =+K5*L5 -> 2.19 | K5: 6 | L5: =+M5/1000 -> 0.365 | M5: =+C5 -> 365
A6: Cordoba | B6: Anjaron | C6: 3007 | D6: 2956 | E6: 2545 | F6: 799 | G6: 2922 | H6: 1787 | J6: =+K6*L6 -> 18.042 | K6: 6 | L6: =+M6/1000 -> 3.007 | M6: =+C6 -> 3007
A7: Cordoba | B7: Arriel | C7: 1173 | D7: 1149 | E7: 969 | F7: 258 | G7: 1148 | H7: 594 | J7: =+K7*L7 -> 7.038 | K7: 6 | L7: =+M7/1000 -> 1.173 | M7: =+C7 -> 1173
A8: Cordoba | B8: Bujalance | C8: 355 | D8: 338 | E8: 260 | F8: 37 | G8: 347 | H8: 131 | J8: =+K8*L8 -> 2.13 | K8: 6 | L8: =+M8/1000 -> 0.355 | M8: =+C8 -> 355
A9: Cordoba | B9: Caballera, De La Santa Maria De Trassierra | C9: 443 | D9: 433 | E9: 376 | F9: 106 | G9: 444 | H9: 285 | J9: =+K9*L9 -> 2.658 | K9: 6 | L9: =+M9/1000 -> 0.443 | M9: =+C9 -> 443
A10: Cordoba | B10: Campiña | C10: 606 | D10: 586 | E10: 468 | F10: 143 | G10: 592 | H10: 295 | J10: =+K10*L10 -> 3.636 | K10: 6 | L10: =+M10/1000 -> 0.606 | M10: =+C10 -> 606
A11: Cordoba | B11: Campiñuela Baja | C11: 2635 | D11: 2595 | E11: 2279 | F11: 775 | G11: 2563 | H11: 1643 | J11: =+K11*L11 -> 15.81 | K11: 6 | L11: =+M11/1000 -> 2.635 | M11: =+C11 -> 2635
A12: Cordoba | B12: Carchena | C12: 1666 | D12: 1638 | E12: 1384 | F12: 393 | G12: 1602 | H12: 915 | J12: =+K12*L12 -> 9.996 | K12: 6 | L12: =+M12/1000 -> 1.666 | M12: =+C12 -> 1666
A13: Cordoba | B13: Castro Del Rio | C13: 491 | D13: 480 | E13: 386 | F13: 102 | G13: 485 | H13: 215 | J13: =+K13*L13 -> 2.946 | K13: 6 | L13: =+M13/1000 -> 0.491 | M13: =+C13 -> 491
... A34: Cuenca | B34: Tarancon | C34: 895 | D34: 872 | E34: 766 | F34: 253 | G34: 880 | H34: 571 | J34: =+K34*L34 -> 5.37 | K34: 6 | L34: =+M34/1000 -> 0.895 | M34: =+C34 -> 895
A35: Gerona - Gerona | B35: Alp | C35: 391 | D35: 370 | E35: 245 | F35: 98 | G35: 364 | H35: 204 | J35: 7.422 | K35: 6 | L35: 1.237 | M35: 1237
A36: Gerona - Gerona | B36: Angles | C36: 324 | D36: 315 | E36: 258 | F36: 70 | G36: 316 | H36: 185 | J36: 7.932 | K36: 6 | L36: 1.322 | M36: 1322
A37: Gerona - Gerona | B37: Arbucies | C37: 536 | D37: 511 | E37: 407 | F37: 125 | G37: 513 | H37: 280 | J37: 2.754 | K37: 6 | L37: 0.459 | M37: 459
A38: Gerona - Gerona | B38: Batet (Ayto Ribes Freser) | C38: 455 | D38: 417 | E38: 296 | F38: 110 | G38: 438 | H38: 253 | J38: 2.136 | K38: 6 | L38: 0.356 | M38: 356
A39: Gerona - Gerona | B39: Beget | C39: 481 | D39: 473 | E39: 357 | F39: 104 | G39: 473 | H39: 271 | J39: =+K39*L39 -> 2.886 | K39: 6 | L39: =+M39/1000 -> 0.481 | M39: =+C39 -> 481
A40: Gerona - Gerona | B40: Beguda | C40: 317 | D40: 309 | E40: 241 | F40: 91 | G40: 310 | H40: 187 | J40: 2.286 | K40: 6 | L40: 0.381 | M40: 381
A41: Gerona - Gerona | B41: Besalu | C41: 466 | D41: 446 | E41: 320 | F41: 108 | G41: 452 | H41: 250 | J41: 10.122 | K41: 6 | L41: 1.687 | M41: 1687
A42: Gerona - Gerona | B42: Bescano | C42: 374 | D42: 358 | E42: 317 | F42: 93 | G42: 360 | H42: 223 | J42: 10.674 | K42: 6 | L42: 1.779 | M42: 1779
A43: Gerona - Gerona | B43: Borgonya | C43: 358 | D43: 348 | E43: 280 | F43: 97 | G43: 340 | H43: 248 | J43: 6.552 | K43: 6 | L43: 1.092 | M43: 1092
A44: Gerona - Gerona | B44: Boscdetosca | C44: 372 | D44: 356 | E44: 271 | F44: 105 | G44: 356 | H44: 213 | J44: 4.068 | K44: 6 | L44: 0.678 | M44: 678
A45: Gerona - Gerona | B45: Breda | C45: 316 | D45: 306 | E45: 249 | F45: 70 | G45: 305 | H45: 164 | J45: 4.344 | K45: 6 | L45: 0.724 | M45: 724
A46: Gerona - Gerona | B46: Cadaques | C46: 641 | D46: 628 | E46: 470 | F46: 153 | G46: 638 | H46: 361 | J46: =+K46*L46 -> 3.846 | K46: 6 | L46: =+M46/1000 -> 0.641 | M46: =+C46 -> 641
A47: Gerona - Gerona | B47: Caldes De Malavella | C47: 438 | D47: 425 | E47: 327 | F47: 106 | G47: 415 | H47: 251 | J47: 1.812 | K47: 6 | L47: 0.302 | M47: 302
A48: Gerona - Gerona | B48: Calonge | C48: 492 | D48: 482 | E48: 373 | F48: 145 | G48: 485 | H48: 313 | J48: =+K48*L48 -> 2.952 | K48: 6 | L48: =+M48/1000 -> 0.492 | M48: =+C48 -> 492
A49: Gerona - Gerona | B49: Canyelles (Ayto Tossa) | C49: 977 | D49: 962 | E49: 699 | F49: 214 | G49: 965 | H49: 540 | J49: =+K49*L49 -> 5.862 | K49: 6 | L49: =+M49/1000 -> 0.977 | M49: =+C49 -> 977
A50: Gerona - Gerona | B50: Canyet De Mar | C50: 463 | D50: 444 | E50: 351 | F50: 128 | G50: 460 | H50: 274 | J50: 5.394 | K50: 6 | L50: 0.899 | M50: 899
A51: Gerona - Gerona | B51: Cassa De La Selva | C51: 768 | D51: 749 | E51: 606 | F51: 196 | G51: 731 | H51: 440 | J51: 3.936 | K51: 6 | L51: 0.656 | M51: 656
A52: Gerona - Gerona | B52: Castello D Empuries | C52: 481 | D52: 466 | E52: 364 | F52: 136 | G52: 459 | H52: 291 | J52: =+K52*L52 -> 2.886 | K52: 6 | L52: =+M52/1000 -> 0.481 | M52: =+C52 -> 481
A53: Gerona - Gerona | B53: Celra | C53: 502 | D53: 495 | E53: 395 | F53: 165 | G53: 482 | H53: 345 | J53: =+K53*L53 -> 3.012 | K53: 6 | L53: =+M53/1000 -> 0.502 | M53: =+C53 -> 502
A54: Gerona - Gerona | B54: Colonia Rocafiguera | C54: 949 | D54: 935 | E54: 788 | F54: 220 | G54: 935 | H54: 524 | J54: =+K54*L54 -> 5.694 | K54: 6 | L54: =+M54/1000 -> 0.949 | M54: =+C54 -> 949
A55: Gerona - Gerona | B55: El Far D Emporda | C55: 519 | D55: 482 | E55: 379 | F55: 158 | G55: 492 | H55: 318 | J55: 5.532 | K55: 6 | L55: 0.922 | M55: 922
A56: Gerona - Gerona | B56: El Perello | C56: 370 | D56: 368 | E56: 309 | F56: 113 | G56: 360 | H56: 247 | J56: =+K56*L56 -> 2.22 | K56: 6 | L56: =+M56/1000 -> 0.37 | M56: =+C56 -> 370
A57: Gerona - Gerona | B57: El Port De La Selva | C57: 313 | D57: 298 | E57: 197 | F57: 83 | G57: 304 | H57: 180 | J57: =+K57*L57 -> 1.878 | K57: 6 | L57: =+M57/1000 -> 0.313 | M57: =+C57 -> 313
A58: Gerona - Gerona | B58: Els Masos | C58: 332 | D58: 326 | E58: 239 | F58: 96 | G58: 323 | H58: 207 | J58: =+K58*L58 -> 1.992 | K58: 6 | L58: =+M58/1000 -> 0.332 | M58: =+C58 -> 332
A59: Gerona - Gerona | B59: Empuriabrava | C59: 1103 | D59: 1073 | E59: 883 | F59: 305 | G59: 1089 | H59: 699 | J59: 6.48 | K59: 6 | L59: 1.08 | M59: 1080
A60: Gerona - Gerona | B60: Fogueres De Montsoriu | C60: 443 | D60: 430 | E60: 340 | F60: 106 | G60: 424 | H60: 248 | J60: =+K60*L60 -> 2.658 | K60: 6 | L60: =+M60/1000 -> 0.443 | M60: =+C60 -> 443
...

Sheet lucia 3
A1: provincia | B1: localidad | C1: Nombre | D1: Direccion | E1: Telefono | F1: Mail | G1: Category | H1: Website | J1: precio | K1: cpm | L1: miles | M1: registros
A2: Alicante - Alicante | B2: Castalla | C2: 863 | D2: 841 | E2: 701 | F2: 248 | G2: 843 | H2: 521 | J2: 3.054 | K2: 6 | L2: 0.509 | M2: 509
A3: Almeria | B3: Aguadulce | C3: 1866 | D3: 1815 | E3: 1523 | F3: 393 | G3: 1800 | H3: 991 | J3: =+K3*L3 -> 11.196 | K3: 6 | L3: =+M3/1000 -> 1.866 | M3: =+C3 -> 1866
A4: Almeria | B4: Albox | C4: 881 | D4: 859 | E4: 725 | F4: 216 | G4: 868 | H4: 477 | J4: =+K4*L4 -> 5.286 | K4: 6 | L4: =+M4/1000 -> 0.881 | M4: =+C4 -> 881
A5: Almeria | B5: Almerimar | C5: 514 | D5: 506 | E5: 416 | F5: 91 | G5: 507 | H5: 306 | J5: =+K5*L5 -> 3.084 | K5: 6 | L5: =+M5/1000 -> 0.514 | M5: =+C5 -> 514
A6: Almeria | B6: Antas | C6: 354 | D6: 345 | E6: 277 | F6: 86 | G6: 341 | H6: 189 | J6: =+K6*L6 -> 2.124 | K6: 6 | L6: =+M6/1000 -> 0.354 | M6: =+C6 -> 354
A7: Almeria | B7: Barrio De Archilla | C7: 1145 | D7: 1104 | E7: 909 | F7: 241 | G7: 1100 | H7: 560 | J7: =+K7*L7 -> 6.87 | K7: 6 | L7: =+M7/1000 -> 1.145 | M7: =+C7 -> 1145
A8: Almeria | B8: Berja | C8: 533 | D8: 518 | E8: 420 | F8: 111 | G8: 522 | H8: 260 | J8: =+K8*L8 -> 3.198 | K8: 6 | L8: =+M8/1000 -> 0.533 | M8: =+C8 -> 533
A9: Almeria | B9: Campamento | C9: 806 | D9: 794 | E9: 647 | F9: 220 | G9: 764 | H9: 440 | J9: =+K9*L9 -> 4.836 | K9: 6 | L9: =+M9/1000 -> 0.806 | M9: =+C9 -> 806
A10: Almeria | B10: Campohermoso | C10: 305 | D10: 302 | E10: 264 | F10: 69 | G10: 294 | H10: 148 | J10: =+K10*L10 -> 1.83 | K10: 6 | L10: =+M10/1000 -> 0.305 | M10: =+C10 -> 305
A11: Almeria | B11: El Agua Del Medio | C11: 1157 | D11: 1131 | E11: 917 | F11: 252 | G11: 1134 | H11: 597 | J11: =+K11*L11 -> 6.942 | K11: 6 | L11: =+M11/1000 -> 1.157 | M11: =+C11 -> 1157
A12: Almeria | B12: El Alquian | C12: 308 | D12: 299 | E12: 233 | F12: 50 | G12: 300 | H12: 140 | J12: =+K12*L12 -> 1.848 | K12: 6 | L12: =+M12/1000 -> 0.308 | M12: =+C12 -> 308
A13: Almeria | B13: El Arroyo Franco Y Estella | C13: 418 | D13: 410 | E13: 309 | F13: 103 | G13: 410 | H13: 233 | J13: =+K13*L13 -> 2.508 | K13: 6 | L13: =+M13/1000 -> 0.418 | M13: =+C13 -> 418
A14: Almeria | B14: El Barranquete | C14: 497 | D14: 474 | E14: 332 | F14: 83 | G14: 476 | H14: 200 | J14: =+K14*L14 -> 2.982 | K14: 6 | L14: =+M14/1000 -> 0.497 | M14: =+C14 -> 497
... A84: Badajoz | B84: Villafranca De Los Barros | C84: 846 | D84: 823 | E84: 658 | F84: 162 | G84: 824 | H84: 394 | J84: =+K84*L84 -> 5.076 | K84: 6 | L84: =+M84/1000 -> 0.846 | M84: =+C84 -> 846
A85: Barcelona | B85: Cervello | C85: 421 | D85: 408 | E85: 325 | F85: 95 | G85: 412 | H85: 236 | J85: 2.526 | K85: 6 | L85: 0.421 | M85: 421
A86: Barcelona | B86: L Eixample | C86: 1065 | D86: 1040 | E86: 856 | F86: 280 | G86: 1042 | H86: 661 | J86: =+K86*L86 -> 6.39 | K86: 6 | L86: =+M86/1000 -> 1.065 | M86: =+C86 -> 1065
A87: Burgos | B87: Arcos De La Llana | C87: 411 | D87: 400 | E87: 294 | F87: 130 | G87: 387 | H87: 235 | J87: =+K87*L87 -> 2.466 | K87: 6 | L87: =+M87/1000 -> 0.411 | M87: =+C87 -> 411
A88: Burgos | B88: Azucarera Leopoldo | C88: 2149 | D88: 2103 | E88: 1737 | F88: 539 | G88: 2085 | H88: 1208 | J88: =+K88*L88 -> 12.894 | K88: 6 | L88: =+M88/1000 -> 2.149 | M88: =+C88 -> 2149
A89: Burgos | B89: Briviesca | C89: 521 | D89: 517 | E89: 403 | F89: 126 | G89: 505 | H89: 267 | J89: =+K89*L89 -> 3.126 | K89: 6 | L89: =+M89/1000 -> 0.521 | M89: =+C89 -> 521
A90: Burgos | B90: Lerma | C90: 342 | D90: 330 | E90: 254 | F90: 84 | G90: 341 | H90: 171 | J90: =+K90*L90 -> 2.052 | K90: 6 | L90: =+M90/1000 -> 0.342 | M90: =+C90 -> 342
A91: Burgos | B91: Medina De Pomar | C91: 679 | D91: 665 | E91: 537 | F91: 164 | G91: 662 | H91: 340 | J91: =+K91*L91 -> 4.074 | K91: 6 | L91: =+M91/1000 -> 0.679 | M91: =+C91 -> 679
A92: Burgos | B92: Villarcayo | C92: 402 | D92: 392 | E92: 318 | F92: 72 | G92: 387 | H92: 183 | J92: =+K92*L92 -> 2.412 | K92: 6 | L92: =+M92/1000 -> 0.402 | M92: =+C92 -> 402
A93: Caceres | B93: Arroyo De La Luz | C93: 328 | D93: 318 | E93: 219 | F93: 56 | G93: 316 | H93: 139 | J93: =+K93*L93 -> 1.968 | K93: 6 | L93: =+M93/1000 -> 0.328 | M93: =+C93 -> 328
A94: Caceres | B94: Atalaya | C94: 434 | D94: 422 | E94: 308 | F94: 95 | G94: 408 | H94: 222 | J94: =+K94*L94 -> 2.604 | K94: 6 | L94: =+M94/1000 -> 0.434 | M94: =+C94 -> 434
A95: Caceres | B95: Coria | C95: 886 | D95: 875 | E95: 705 | F95: 180 | G95: 861 | H95: 448 | J95: =+K95*L95 -> 5.316 | K95: 6 | L95: =+M95/1000 -> 0.886 | M95: =+C95 -> 886
A96: Caceres | B96: Hervas | C96: 465 | D96: 455 | E96: 361 | F96: 103 | G96: 456 | H96: 237 | J96: =+K96*L96 -> 2.79 | K96: 6 | L96: =+M96/1000 -> 0.465 | M96: =+C96 -> 465
A97: Caceres | B97: Jaraiz De La Vera | C97: 539 | D97: 522 | E97: 448 | F97: 115 | G97: 521 | H97: 272 | J97: =+K97*L97 -> 3.234 | K97: 6 | L97: =+M97/1000 -> 0.539 | M97: =+C97 -> 539
... A202: Ciudad Real | B202: Villarrubia De Los Ojos | C202: 511 | D202: 489 | E202: 381 | F202: 100 | G202: 493 | H202: 237 | J202: =+K202*L202 -> 3.066 | K202: 6 | L202: =+M202/1000 -> 0.511 | M202: =+C202 -> 511
